<?xml version="1.0"?>

<robot name="castor" xmlns:xacro="http://wiki.ros.org/xacro">
	<xacro:macro name="castor" params="object_name:='castor' parent_link:='base_link' hardware_interface:='hardware_interface/EffortJointInterface' xyz:='0 0 0' rpy:='0 0 0'">
		<xacro:property
			name="mass"
			value="1"/>
		<xacro:property
			name="r"
			value="0.011"/>
		<xacro:property
			name="h"
			value="0.09"/>
		<xacro:property
			name="M_PI"
			value="3.1415926536"/>

		<link
			name="${object_name}_link">
			<inertial>
				<origin
					xyz="0 0 ${-h/2}"
					rpy="0 0 0"/>
				<mass
					value="${mass}"/>
				<inertia
					ixx="${(3 * r * r + h * h ) / 12.0}"
					ixy="0.0"
					ixz="0.0"
					iyy="${(3 * r * r + h * h ) / 12.0}"
					iyz="0.0"
					izz="${(r * r) / 2.0}"/>
			</inertial>
			<visual>
				<origin
					xyz="0 0 ${-h/2}"
					rpy="0 0 0"/>
				<geometry>
					<cylinder
						radius="${r}"
						length="${h}"/>
				</geometry>
				<material
					name="${object_name}_material">
					<color
						rgba="0.15 0.15 0.15 1"/>
					<texture
						filename=""/>
				</material>
			</visual>
			<collision>
				<origin
					xyz="0 0 ${-h/2}"
					rpy="0 0 0"/>
				<geometry>
					<cylinder
						radius="${r}"
						length="${h}"/>
				</geometry>
			</collision>
		</link>

		<joint
			name="${object_name}_joint"
			type="continuous">
			<origin
				xyz="${xyz}"
				rpy="${rpy}"/>
			<parent
				link="${parent_link}"/>
			<child
				link="${object_name}_link"/>
			<axis
				xyz="0 0 1"/>
		</joint>

		<transmission
			name="${object_name}_trans"
			type="SimpleTransmission">
			<type>
				transmission_interface/SimpleTransmission
			</type>
			<joint
				name="${object_name}_joint">
				<hardwareInterface>
					${hardware_interface}
				</hardwareInterface>
			</joint>
			<actuator
				name="${object_name}_actuator">
				<mechanicalReduction>
					1
				</mechanicalReduction>
			</actuator>
		</transmission>

		<gazebo reference="${object_name}_link">
			<material>Gazebo/Grey</material>
			<gravity>true</gravity>
			<kp>1000.0</kp>
			<kd>1.0</kd>
			<mu1>0.8</mu1>
			<mu2>0.8</mu2>
			<maxVel>0.0</maxVel>
			<minDepth>0.001</minDepth>
		</gazebo>

	</xacro:macro>
</robot>