<?xml version="1.0"?>

<robot name="castor_wheel" xmlns:xacro="http://wiki.ros.org/xacro">
	<xacro:macro name="castor_wheel" params="object_name:='castor' parent_link:='base_link' xyz:='0 0 0' rpy:='0 0 0'">
		<xacro:property
			name="mass"
			value="1"/>
		<xacro:property
			name="ri"
			value="0.06"/>
		<xacro:property
			name="ro"
			value="0.045"/>
		<xacro:property
			name="h"
			value="0.03"/>
		<xacro:property
			name="mass_rod"
			value="1"/>
		<xacro:property
			name="r_rod"
			value="0.02"/>
		<xacro:property
			name="h_rod"
			value="0.068"/>
		<xacro:property
			name="M_PI"
			value="3.1415926536"/>

		<link
			name="${object_name}_rod">
			<inertial>
				<origin
					xyz="0 0 ${-h_rod/2}"
					rpy="0 0 0"/>
				<mass
					value="${mass_rod}"/>
				<inertia
					ixx="${(3 * r_rod * r_rod + h_rod * h_rod) / 12.0}"
					ixy="0.0"
					ixz="0.0"
					iyy="${(3 * r_rod * r_rod + h_rod * h_rod) / 12.0}"
					iyz="0.0"
					izz="${(r_rod * r_rod) / 2.0}"/>
			</inertial>
			<visual>
				<origin
					xyz="0 0 ${-h_rod/2}"
					rpy="0 0 0"/>
				<geometry>
					<cylinder
						radius="${r_rod}"
						length="${h_rod}"/>
				</geometry>
				<material
					name="${object_name}_rod_material">
					<color
						rgba="0.15 0.15 0.15 1"/>
					<texture
						filename=""/>
				</material>
			</visual>
			<collision>
				<origin
					xyz="0 0 ${-h_rod/2}"
					rpy="0 0 0"/>
				<geometry>
					<cylinder
						radius="${r_rod}"
						length="${h_rod}"/>
				</geometry>
			</collision>
		</link>

		<joint
			name="${object_name}_rod_joint"
			type="continuous">
			<origin
				xyz="${xyz}"
				rpy="${rpy}"/>
			<parent
				link="${parent_link}"/>
			<child
				link="${object_name}_rod"/>
			<axis
				xyz="0 0 1"/>
		</joint>

		<transmission
			name="${object_name}_rod_trans"
			type="SimpleTransmission">
			<type>
				transmission_interface/SimpleTransmission
			</type>
			<joint
				name="${object_name}_rod_joint">
				<hardwareInterface>
					hardware_interface/EffortJointInterface
				</hardwareInterface>
			</joint>
			<actuator
				name="${object_name}_rod_actuator">
				<mechanicalReduction>
					1
				</mechanicalReduction>
			</actuator>
		</transmission>

		<gazebo reference="${object_name}_rod">
			<material>Gazebo/Grey</material>
			<kp>100000.0</kp>
			<kd>10000.0</kd>
			<mu1>0.8</mu1>
			<mu2>0.8</mu2>
		</gazebo>

		<link
			name="${object_name}">
			<inertial>
				<origin
					xyz="0 0 0"
					rpy="0 0 0"/>
				<mass
					value="${mass}"/>
				<inertia
					ixx="${(3 * (ro * ro + ri * ri) + h * h) / 12.0}"
					iyy="${(3 * (ro * ro + ri * ri) + h * h) / 12.0}"
					izz="${(ro * ro + ri * ri) / 2.0}"
					ixy="0.0"
					ixz="0.0"
					iyz="0.0"/>
			</inertial>
			<visual>
				<origin
					xyz="0 0 0"
					rpy="0 0 0"/>
				<geometry>
					<cylinder
						radius="${ro}"
						length="${h}"/>
				</geometry>
				<material
					name="${object_name}_material">
					<color
						rgba="0 0 0 1"/>
					<texture
						filename=""/>
				</material>
			</visual>
			<collision>
				<origin
					xyz="0 0 0"
					rpy="0 0 0"/>
				<geometry>
					<cylinder
						radius="${ro}"
						length="${h}"/>
				</geometry>
			</collision>
		</link>

		<joint
			name="${object_name}_joint"
			type="continuous">
			<origin
				xyz="${ro/2} 0 ${-h_rod}"
				rpy="${-90*M_PI/180} 0 0"/>
			<parent
				link="${object_name}_rod"/>
			<child
				link="${object_name}"/>
			<axis
				xyz="0 0 1"/>
		</joint>

		<transmission
			name="${object_name}_trans"
			type="SimpleTransmission">
			<type>
				transmission_interface/SimpleTransmission
			</type>
			<joint
				name="${object_name}_joint">
				<hardwareInterface>
					hardware_interface/EffortJointInterface
				</hardwareInterface>
			</joint>
			<actuator
				name="${object_name}_actuator">
				<mechanicalReduction>
					1
				</mechanicalReduction>
			</actuator>
		</transmission>

		<gazebo reference="${object_name}">
			<material>Gazebo/Black</material>
			<kp>100000.0</kp>
			<kd>10000.0</kd>
			<mu1>1.0</mu1>
			<mu2>1.0</mu2>
		</gazebo>

	</xacro:macro>
</robot>